<?xml version="1.0"?>
<robot name="quadrotor/quadrotor">

    <macro name="frame_inertia">
        <inertia ixx="1.231E-04" ixy="-3.560E-08" ixz="4.131E-07"
                 iyy="1.218E-04" iyz="4.210E-07"
                 izz="1.942E-04" />
    </macro>

    <macro name="propellers_holder_inertia">
        <inertia ixx="0.00" ixy="0.00" ixz="0.00"
                 iyy="0.00" iyz="0.00"
                 izz="0.00" />
    </macro>

    <macro name="propellers_inertia">
        <inertia ixx="3.962E-06" ixy="0.00" ixz="-8.233E-10"
                 iyy="6.100E-06" iyz="0.00"
                 izz="6.716E-06" />
    </macro>

    <property name="PI" value="3.1415926535897931" />
    <property name="frame_file_path" value="/home/nptttn/senior_project/ros/quadrotor/src/quad_sim/urdf/meshes/final_frame.stl" />
    <property name="propeller_base_file_path" value="/home/nptttn/senior_project/ros/quadrotor/src/quad_sim/urdf/meshes/KV2540_Motor_Base.stl" />
    <property name="propeller_file_path" value="/home/nptttn/senior_project/ros/quadrotor/src/quad_sim/urdf/meshes/KV2540_Motor_Propeller_holder.stl" />
    
    <macro name="propeller_holder_link" params="name">
        <link name="${name}">
            <inertial>
                <mass value="0.01696" />
                <origin xyz="0 0 0" rpy="0 0 0" />
                <propellers_holder_inertia />
            </inertial>
            <visual>
                <origin xyz="0 0 0" rpy="0 0 0" />
                <geometry>
                    <mesh filename="${propeller_base_file_path}" scale="0.001 0.001 0.001" />
                </geometry>
            </visual>
            <collision>
                <origin xyz="0 0 0" rpy="0 0 0" />
                <geometry>
                    <mesh filename="${propeller_base_file_path}" scale="0.001 0.001 0.001" />
                </geometry>
            </collision>
        </link>
    </macro>

    <macro name="propeller_link" params="name">
        <link name="${name}">
            <inertial>
                <mass value="0.01696" />
                <origin xyz="0 0 0" rpy="0 0 0" />
                <propellers_inertia />
            </inertial>
            <visual>
                <origin xyz="0 0 0" rpy="0 0 0" />
                <geometry>
                    <mesh filename="${propeller_file_path}" scale="0.001 0.001 0.001" />
                </geometry>
            </visual>
            <collision>
                <origin xyz="0 0 0" rpy="0 0 0" />
                <geometry>
                    <mesh filename="${propeller_file_path}" scale="0.001 0.001 0.001" />
                </geometry>
            </collision>
        </link>
    </macro>

    <link name="frame">
        <inertial>
            <mass value="0.061399" />
            <origin xyz="-0.11 0.11 0" rpy="0 0 0" />
            <frame_inertia />
        </inertial>
        <visual>
            <origin xyz="-0.11 0.11 0" rpy="${PI/2} 0 0" />
            <geometry>
                <mesh filename="${frame_file_path}" scale="0.001 0.001 0.001" />
            </geometry>
        </visual>
        <collision>
            <origin xyz="-0.11 0.11 0" rpy="${PI/2} 0 0" />
            <geometry>
                <mesh filename="${frame_file_path}" scale="0.001 0.001 0.001" />
            </geometry>
        </collision>
    </link>

    <propeller_holder_link name="propeller_holder1"/>

    <joint name="body_propeller1" type="fixed">
        <origin xyz="0.095 -0.095 0.08" rpy="${PI/2} 0 0" />
        <parent link="frame" />
        <child link="propeller_holder1" />
    </joint>

    <propeller_holder_link name="propeller_holder2" />

    <joint name="body_propeller2" type="fixed">
        <origin xyz="-0.095 0.095 0.08" rpy="${PI/2} 0 0" />
        <parent link="frame" />
        <child link="propeller_holder2" />
    </joint>

    <propeller_holder_link name="propeller_holder3" />

    <joint name="body_propeller3" type="fixed">
        <origin xyz="0.095 0.095 0.08" rpy="${PI/2} 0 0" />
        <parent link="frame" />
        <child link="propeller_holder3" />
    </joint>

    <propeller_holder_link name="propeller_holder4" />

    <joint name="body_propeller4" type="fixed">
        <origin xyz="-0.095 -0.095 0.08" rpy="${PI/2} 0 0" />
        <parent link="frame" />
        <child link="propeller_holder4" />
    </joint>



    <propeller_link name="propeller1"/>

    <joint name="propeller_base_propeller1" type="continuous">
        <origin xyz="0.095 -0.095 0.081" rpy="${PI/2} 0 0" />
        <parent link="frame" />
        <child link="propeller1" />
        <axis xyz="0 1 0" />
        <dynamics damping="0.0004" friction="0.00"/>
    </joint>

    <propeller_link name="propeller2" />

    <joint name="propeller_base_propeller2" type="continuous">
        <origin xyz="-0.095 0.095 0.081" rpy="${PI/2} 0 0" />
        <parent link="frame" />
        <child link="propeller2" />
        <axis xyz="0 1 0" />
        <dynamics damping="0.0004" friction="0.00"/>
    </joint>

    <propeller_link name="propeller3" />
1
    <joint name="propeller_base_propeller3" type="continuous">
        <origin xyz="0.095 0.095 0.081" rpy="${PI/2} 0 0" />
        <parent link="frame" />
        <child link="propeller3" />
        <axis xyz="0 1 0" />
        <dynamics damping="0.0004" friction="0.00"/>
    </joint>

    <propeller_link name="propeller4" />

    <joint name="propeller_base_propeller4" type="continuous">
        <origin xyz="-0.095 -0.095 0.081" rpy="${PI/2} 0 0" />
        <parent link="frame" />
        <child link="propeller4" />
        <axis xyz="0 1 0" />
        <dynamics damping="0.0004" friction="0.00"/>
    </joint>
    
    <gazebo>
        <plugin name="quad_liftforce_plugins" filename="libquad_liftforce_plugins.so">
            <robotNamespace>quad_sim</robotNamespace>
            <propeller1_link>propeller1</propeller1_link>
            <propeller2_link>propeller2</propeller2_link>
            <propeller3_link>propeller3</propeller3_link>
            <propeller4_link>propeller4</propeller4_link>
            <topicName>throttle</topicName>
        </plugin>
    </gazebo>

</robot>